Workbook

Sheet 🏠메인대시보드
A1: 🌊 ○○시 상수도사업소 통합관리 대시보드
A3: 2025년 1월 ~ 6월 반기 현황 | 7개 관리시트 연동 | 최종 업데이트: 2025-06-30
A5: 💧 6월 총급수량 | E5: 📊 6월 유수율 | I5: 💰 6월 수납율 | M5: 📞 6월 민원건수
A7: =SUM(①급수량관리!E31:E35) -> 108200 | E7: =③누수_유수율!E11 -> 0 | I7: =④요금수입!D11 -> 0 | M7: =SUMIF(⑤민원관리!A26:A29,"2025-06",⑤민원관리!C26:C29) -> 19
A10: ㎥ | M10: 건
A14: 📈 월별 총 급수량 현황 (1월~6월)
A15: 구분 | B15: 1월 | C15: 2월 | D15: 3월 | E15: 4월 | F15: 5월 | G15: 6월
A16: 중앙구 | B16: =①급수량관리!E5 -> 43200 | C16: =①급수량관리!E10 -> 44100 | D16: =①급수량관리!E15 -> 46200 | E16: =①급수량관리!E20 -> 47500 | F16: =①급수량관리!E25 -> 49100 | G16: =①급수량관리!E30 -> 51200
A17: 동부구 | B17: =①급수량관리!E6 -> 31500 | C17: =①급수량관리!E11 -> 31800 | D17: =①급수량관리!E16 -> 32700 | E17: =①급수량관리!E21 -> 33600 | F17: =①급수량관리!E26 -> 34500 | G17: =①급수량관리!E31 -> 35400
A18: 서부구 | B18: =①급수량관리!E7 -> 27800 | C18: =①급수량관리!E12 -> 28200 | D18: =①급수량관리!E17 -> 28900 | E18: =①급수량관리!E22 -> 29800 | F18: =①급수량관리!E27 -> 30600 | G18: =①급수량관리!E32 -> 31500
A19: 남부구 | B19: =①급수량관리!E8 -> 18600 | C19: =①급수량관리!E13 -> 18900 | D19: =①급수량관리!E18 -> 19800 | E19: =①급수량관리!E23 -> 20700 | F19: =①급수량관리!E28 -> 21800 | G19: =①급수량관리!E33 -> 22600
A20: 북부구 | B20: =①급수량관리!E9 -> 14900 | C20: =①급수량관리!E14 -> 15100 | D20: =①급수량관리!E19 -> 15900 | E20: =①급수량관리!E24 -> 16800 | F20: =①급수량관리!E29 -> 17900 | G20: =①급수량관리!E34 -> 18700
A21: 합 계 | B21: =SUM(B16:B20) -> 136000 | C21: =SUM(C16:C20) -> 138100 | D21: =SUM(D16:D20) -> 143500 | E21: =SUM(E16:E20) -> 148400 | F21: =SUM(F16:F20) -> 153900 | G21: =SUM(G16:G20) -> 159400
A23: 📊 월별 유수율 및 누수 현황 (③누수_유수율 연동)
A24: 구분 | B24: 1월 | C24: 2월 | D24: 3월 | E24: 4월 | F24: 5월 | G24: 6월
A25: 총생산수량(㎥) | B25: =③누수_유수율!B5 -> 145000 | C25: =③누수_유수율!B6 -> 142000 | D25: =③누수_유수율!B7 -> 149000 | E25: =③누수_유수율!B8 -> 154000 | F25: =③누수_유수율!B9 -> 160000 | G25: =③누수_유수율!B10 -> 165000
A26: 총급수수량(㎥) | B26: =③누수_유수율!C5 -> 136000 | C26: =③누수_유수율!C6 -> 134500 | D26: =③누수_유수율!C7 -> 140800 | E26: =③누수_유수율!C8 -> 146200 | F26: =③누수_유수율!C9 -> 152500 | G26: =③누수_유수율!C10 -> 567677
A27: 누수량(㎥) | B27: =③누수_유수율!D5 -> 10000 | C27: =③누수_유수율!D6 -> 7500 | D27: =③누수_유수율!D7 -> 2333 | E27: =③누수_유수율!D8 -> 4444 | F27: =③누수_유수율!D9 -> 7500 | G27: =③누수_유수율!D10 -> 7800
A28: 유수율(%) | B28: =③누수_유수율!E5 -> 0.93793103 | C28: =③누수_유수율!E6 -> 0.9471831 | D28: =③누수_유수율!E7 -> 0.94496644 | E28: =③누수_유수율!E8 -> 0.94935065 | F28: =③누수_유수율!E9 -> 0.953125 | G28: =③누수_유수율!E10 -> 3.4404667
A29: 누수건수(건) | B29: =③누수_유수율!G5 -> 12 | C29: =③누수_유수율!G6 -> 9 | D29: =③누수_유수율!G7 -> 11 | E29: =③누수_유수율!G8 -> 8 | F29: =③누수_유수율!G9 -> 8 | G29: =③누수_유수율!G10 -> 7
A31: 💰 월별 요금수입 현황 (④요금수입 연동)
A32: 구분 | B32: 1월 | C32: 2월 | D32: 3월 | E32: 4월 | F32: 5월 | G32: 6월 | H32: 상반기합계
A33: 고지금액(원) | B33: =④요금수입!B5 -> 185200000 | C33: =④요금수입!B6 -> 179800000 | D33: =④요금수입!B7 -> 192500000 | E33: =④요금수입!B8 -> 198700000 | F33: =④요금수입!B9 -> 206300000 | G33: =④요금수입!B10 -> 215800000 | H33: =SUM(B33:G33) -> 1178300000
A34: 수납금액(원) | B34: =④요금수입!C5 -> 181356000 | C34: =④요금수입!C6 -> 176204000 | D34: =④요금수입!C7 -> 188930000 | E34: =④요금수입!C8 -> 195726000 | F34: =④요금수입!C9 -> 203418000 | G34: =④요금수입!C10 -> 212813000 | H34: =SUM(B34:G34) -> 1158447000
A35: 수납율(%) | B35: =④요금수입!D5 -> 0.97924406 | C35: =④요금수입!D6 -> 0.98 | D35: =④요금수입!D7 -> 0.98145455 | E35: =④요금수입!D8 -> 0.98503271 | F35: =④요금수입!D9 -> 0.98603005 | G35: =④요금수입!D10 -> 0.98615848 | H35: =AVERAGE(B35:G35) -> 0.98298664
A36: 체납금액(원) | B36: =④요금수입!E5 -> 3844000 | C36: =④요금수입!E6 -> 3596000 | D36: =④요금수입!E7 -> 3570000 | E36: =④요금수입!E8 -> 2974000 | F36: =④요금수입!E9 -> 2882000 | G36: =④요금수입!E10 -> 2987000 | H36: =SUM(B36:G36) -> 19853000
A37: 체납건수(건) | B37: =④요금수입!F5 -> 42 | C37: =④요금수입!F6 -> 38 | D37: =④요금수입!F7 -> 35 | E37: =④요금수입!F8 -> 30 | F37: =④요금수입!F9 -> 28 | G37: =④요금수입!F10 -> 31 | H37: =SUM(B37:G37) -> 204
A39: 📞 월별 민원 현황 (⑤민원관리 연동)
A40: 구분 | B40: 1월 | C40: 2월 | D40: 3월 | E40: 4월 | F40: 5월 | G40: 6월 | H40: 합계
A41: 수도누수신고 | B41: =SUMPRODUCT((⑤민원관리!$A$5:$A$28="2025-01")*(⑤민원관리!$B$5:$B$28="수도누수신고")*⑤민원관리!$C$5:$C$28) -> 18 | C41: =SUMPRODUCT((⑤민원관리!$A$5:$A$28="2025-02")*(⑤민원관리!$B$5:$B$28="수도누수신고")*⑤민원관리!$C$5:$C$28) -> 14 | D41: =SUMPRODUCT((⑤민원관리!$A$5:$A$28="2025-03")*(⑤민원관리!$B$5:$B$28="수도누수신고")*⑤민원관리!$C$5:$C$28) -> 16 | E41: =SUMPRODUCT((⑤민원관리!$A$5:$A$28="2025-04")*(⑤민원관리!$B$5:$B$28="수도누수신고")*⑤민원관리!$C$5:$C$28) -> 12 | F41: =SUMPRODUCT((⑤민원관리!$A$5:$A$28="2025-05")*(⑤민원관리!$B$5:$B$28="수도누수신고")*⑤민원관리!$C$5:$C$28) -> 15 | G41: =SUMPRODUCT((⑤민원관리!$A$5:$A$28="2025-06")*(⑤민원관리!$B$5:$B$28="수도누수신고")*⑤민원관리!$C$5:$C$28) -> 20 | H41: =SUM(B41:G41) -> 95
A42: 요금이의신청 | B42: =SUMPRODUCT((⑤민원관리!$A$5:$A$28="2025-01")*(⑤민원관리!$B$5:$B$28="요금이의신청")*⑤민원관리!$C$5:$C$28) -> 5 | C42: =SUMPRODUCT((⑤민원관리!$A$5:$A$28="2025-02")*(⑤민원관리!$B$5:$B$28="요금이의신청")*⑤민원관리!$C$5:$C$28) -> 4 | D42: =SUMPRODUCT((⑤민원관리!$A$5:$A$28="2025-03")*(⑤민원관리!$B$5:$B$28="요금이의신청")*⑤민원관리!$C$5:$C$28) -> 6 | E42: =SUMPRODUCT((⑤민원관리!$A$5:$A$28="2025-04")*(⑤민원관리!$B$5:$B$28="요금이의신청")*⑤민원관리!$C$5:$C$28) -> 3 | F42: =SUMPRODUCT((⑤민원관리!$A$5:$A$28="2025-05")*(⑤민원관리!$B$5:$B$28="요금이의신청")*⑤민원관리!$C$5:$C$28) -> 4 | G42: =SUMPRODUCT((⑤민원관리!$A$5:$A$28="2025-06")*(⑤민원관리!$B$5:$B$28="요금이의신청")*⑤민원관리!$C$5:$C$28) -> 5 | H42: =SUM(B42:G42) -> 27
A43: 수압불량 | B43: =SUMPRODUCT((⑤민원관리!$A$5:$A$28="2025-01")*(⑤민원관리!$B$5:$B$28="수압불량")*⑤민원관리!$C$5:$C$28) -> 8 | C43: =SUMPRODUCT((⑤민원관리!$A$5:$A$28="2025-02")*(⑤민원관리!$B$5:$B$28="수압불량")*⑤민원관리!$C$5:$C$28) -> 6 | D43: =SUMPRODUCT((⑤민원관리!$A$5:$A$28="2025-03")*(⑤민원관리!$B$5:$B$28="수압불량")*⑤민원관리!$C$5:$C$28) -> 9 | E43: =SUMPRODUCT((⑤민원관리!$A$5:$A$28="2025-04")*(⑤민원관리!$B$5:$B$28="수압불량")*⑤민원관리!$C$5:$C$28) -> 5 | F43: =SUMPRODUCT((⑤민원관리!$A$5:$A$28="2025-05")*(⑤민원관리!$B$5:$B$28="수압불량")*⑤민원관리!$C$5:$C$28) -> 7 | G43: =SUMPRODUCT((⑤민원관리!$A$5:$A$28="2025-06")*(⑤민원관리!$B$5:$B$28="수압불량")*⑤민원관리!$C$5:$C$28) -> 10 | H43: =SUM(B43:G43) -> 45
A44: 단수불편 | B44: =SUMPRODUCT((⑤민원관리!$A$5:$A$28="2025-01")*(⑤민원관리!$B$5:$B$28="단수불편")*⑤민원관리!$C$5:$C$28) -> 3 | C44: =SUMPRODUCT((⑤민원관리!$A$5:$A$28="2025-02")*(⑤민원관리!$B$5:$B$28="단수불편")*⑤민원관리!$C$5:$C$28) -> 2 | D44: =SUMPRODUCT((⑤민원관리!$A$5:$A$28="2025-03")*(⑤민원관리!$B$5:$B$28="단수불편")*⑤민원관리!$C$5:$C$28) -> 0 | E44: =SUMPRODUCT((⑤민원관리!$A$5:$A$28="2025-04")*(⑤민원관리!$B$5:$B$28="단수불편")*⑤민원관리!$C$5:$C$28) -> 0 | F44: =SUMPRODUCT((⑤민원관리!$A$5:$A$28="2025-05")*(⑤민원관리!$B$5:$B$28="단수불편")*⑤민원관리!$C$5:$C$28) -> 2 | G44: =SUMPRODUCT((⑤민원관리!$A$5:$A$28="2025-06")*(⑤민원관리!$B$5:$B$28="단수불편")*⑤민원관리!$C$5:$C$28) -> 4 | H44: =SUM(B44:G44) -> 11
A45: 기타불편 | B45: =SUMPRODUCT((⑤민원관리!$A$5:$A$28="2025-01")*(⑤민원관리!$B$5:$B$28="기타불편")*⑤민원관리!$C$5:$C$28) -> 0 | C45: =SUMPRODUCT((⑤민원관리!$A$5:$A$28="2025-02")*(⑤민원관리!$B$5:$B$28="기타불편")*⑤민원관리!$C$5:$C$28) -> 0 | D45: =SUMPRODUCT((⑤민원관리!$A$5:$A$28="2025-03")*(⑤민원관리!$B$5:$B$28="기타불편")*⑤민원관리!$C$5:$C$28) -> 4 | E45: =SUMPRODUCT((⑤민원관리!$A$5:$A$28="2025-04")*(⑤민원관리!$B$5:$B$28="기타불편")*⑤민원관리!$C$5:$C$28) -> 3 | F45: =SUMPRODUCT((⑤민원관리!$A$5:$A$28="2025-05")*(⑤민원관리!$B$5:$B$28="기타불편")*⑤민원관리!$C$5:$C$28) -> 0 | G45: =SUMPRODUCT((⑤민원관리!$A$5:$A$28="2025-06")*(⑤민원관리!$B$5:$B$28="기타불편")*⑤민원관리!$C$5:$C$28) -> 0 | H45: =SUM(B45:G45) -> 7
A46: 총 합계 | B46: =SUM(B41:B45) -> 34 | C46: =SUM(C41:C45) -> 26 | D46: =SUM(D41:D45) -> 35 | E46: =SUM(E41:E45) -> 23 | F46: =SUM(F41:F45) -> 28 | G46: =SUM(G41:G45) -> 39 | H46: =SUM(H41:H45) -> 185
A48: 📋 월별 예산집행 현황 (⑦예산집행 연동)
A49: 예산항목 | B49: 1월 | C49: 2월 | D49: 3월 | E49: 4월 | F49: 5월 | G49: 6월 | H49: 상반기합계
A50: 인건비 | B50: =⑦예산집행!D5 -> 24850000 | C50: =⑦예산집행!D9 -> 24950000 | D50: =⑦예산집행!D13 -> 24900000 | E50: =⑦예산집행!D17 -> 25000000 | F50: =⑦예산집행!D21 -> 24980000 | G50: =⑦예산집행!D25 -> 24970000 | H50: =SUM(B50:G50) -> 149650000
A51: 운영비 | B51: =⑦예산집행!D6 -> 7920000 | C51: =⑦예산집행!D10 -> 8100000 | D51: =⑦예산집행!D14 -> 8250000 | E51: =⑦예산집행!D18 -> 8320000 | F51: =⑦예산집행!D22 -> 8400000 | G51: =⑦예산집행!D26 -> 8480000 | H51: =SUM(B51:G51) -> 49470000
A52: 시설유지보수 | B52: =⑦예산집행!D7 -> 9800000 | C52: =⑦예산집행!D11 -> 4200000 | D52: =⑦예산집행!D15 -> 12500000 | E52: =⑦예산집행!D19 -> 5600000 | F52: =⑦예산집행!D23 -> 7800000 | G52: =⑦예산집행!D27 -> 8200000 | H52: =SUM(B52:G52) -> 48100000
...

Sheet ①급수량관리
A1: 💧 급수량 관리대장
A2: ○○시 상수도사업소 | 2025년 1월~6월
A4: 연월 | B4: 구역코드 | C4: 구역명 | D4: 계획급수량(㎥) | E4: 실제급수량(㎥) | F4: 달성률(%) | G4: 전월대비증감(㎥) | H4: 증감률(%) | I4: 누계급수량(㎥) | J4: 비고
A5: 2025-01 | B5: A-01 | C5: 중앙구 | D5: 45000 | E5: 43200 | F5: =E5/D5 -> 0.96 | I5: =SUMIF($B$5:B5,B5,$E$5:E5) -> 43200 | J5: 동절기 감소
A6: 2025-01 | B6: A-02 | C6: 동부구 | D6: 32000 | E6: 31500 | F6: =E6/D6 -> 0.984375 | I6: =SUMIF($B$5:B6,B6,$E$5:E6) -> 31500
A7: 2025-01 | B7: A-03 | C7: 서부구 | D7: 28000 | E7: 27800 | F7: =E7/D7 -> 0.99285714 | I7: =SUMIF($B$5:B7,B7,$E$5:E7) -> 27800
A8: 2025-01 | B8: A-04 | C8: 남부구 | D8: 19000 | E8: 18600 | F8: =E8/D8 -> 0.97894737 | I8: =SUMIF($B$5:B8,B8,$E$5:E8) -> 18600
A9: 2025-01 | B9: A-05 | C9: 북부구 | D9: 15000 | E9: 14900 | F9: =E9/D9 -> 0.99333333 | I9: =SUMIF($B$5:B9,B9,$E$5:E9) -> 14900 | J9: 신규 배관
A10: 2025-02 | B10: A-01 | C10: 중앙구 | D10: 45000 | E10: 44100 | F10: =E10/D10 -> 0.98 | G10: =E10-E5 -> 900 | H10: =G10/E5 -> 0.020833333 | I10: =SUMIF($B$5:B10,B10,$E$5:E10) -> 87300
A11: 2025-02 | B11: A-02 | C11: 동부구 | D11: 32000 | E11: 31800 | F11: =E11/D11 -> 0.99375 | G11: =E11-E6 -> 300 | H11: =G11/E6 -> 0.0095238095 | I11: =SUMIF($B$5:B11,B11,$E$5:E11) -> 63300
A12: 2025-02 | B12: A-03 | C12: 서부구 | D12: 28000 | E12: 28200 | F12: =E12/D12 -> 1.0071429 | G12: =E12-E7 -> 400 | H12: =G12/E7 -> 0.014388489 | I12: =SUMIF($B$5:B12,B12,$E$5:E12) -> 56000
A13: 2025-02 | B13: A-04 | C13: 남부구 | D13: 19000 | E13: 18900 | F13: =E13/D13 -> 0.99473684 | G13: =E13-E8 -> 300 | H13: =G13/E8 -> 0.016129032 | I13: =SUMIF($B$5:B13,B13,$E$5:E13) -> 37500
A14: 2025-02 | B14: A-05 | C14: 북부구 | D14: 15000 | E14: 15100 | F14: =E14/D14 -> 1.0066667 | G14: =E14-E9 -> 200 | H14: =G14/E9 -> 0.013422819 | I14: =SUMIF($B$5:B14,B14,$E$5:E14) -> 30000
A15: 2025-03 | B15: A-01 | C15: 중앙구 | D15: 47000 | E15: 46200 | F15: =E15/D15 -> 0.98297872 | G15: =E15-E10 -> 2100 | H15: =G15/E10 -> 0.047619048 | I15: =SUMIF($B$5:B15,B15,$E$5:E15) -> 133500
A16: 2025-03 | B16: A-02 | C16: 동부구 | D16: 33000 | E16: 32700 | F16: =E16/D16 -> 0.99090909 | G16: =E16-E11 -> 900 | H16: =G16/E11 -> 0.028301887 | I16: =SUMIF($B$5:B16,B16,$E$5:E16) -> 96000
A17: 2025-03 | B17: A-03 | C17: 서부구 | D17: 29000 | E17: 28900 | F17: =E17/D17 -> 0.99655172 | G17: =E17-E12 -> 700 | H17: =G17/E12 -> 0.024822695 | I17: =SUMIF($B$5:B17,B17,$E$5:E17) -> 84900
A18: 2025-03 | B18: A-04 | C18: 남부구 | D18: 20000 | E18: 19800 | F18: =E18/D18 -> 0.99 | G18: =E18-E13 -> 900 | H18: =G18/E13 -> 0.047619048 | I18: =SUMIF($B$5:B18,B18,$E$5:E18) -> 57300
A19: 2025-03 | B19: A-05 | C19: 북부구 | D19: 16000 | E19: 15900 | F19: =E19/D19 -> 0.99375 | G19: =E19-E14 -> 800 | H19: =G19/E14 -> 0.052980132 | I19: =SUMIF($B$5:B19,B19,$E$5:E19) -> 45900
A20: 2025-04 | B20: A-01 | C20: 중앙구 | D20: 48000 | E20: 47500 | F20: =E20/D20 -> 0.98958333 | G20: =E20-E15 -> 1300 | H20: =G20/E15 -> 0.028138528 | I20: =SUMIF($B$5:B20,B20,$E$5:E20) -> 181000
A21: 2025-04 | B21: A-02 | C21: 동부구 | D21: 34000 | E21: 33600 | F21: =E21/D21 -> 0.98823529 | G21: =E21-E16 -> 900 | H21: =G21/E16 -> 0.027522936 | I21: =SUMIF($B$5:B21,B21,$E$5:E21) -> 129600
... A24: 2025-04 | B24: A-05 | C24: 북부구 | D24: 17000 | E24: 16800 | F24: =E24/D24 -> 0.98823529 | G24: =E24-E19 -> 900 | H24: =G24/E19 -> 0.056603774 | I24: =SUMIF($B$5:B24,B24,$E$5:E24) -> 62700
A25: 2025-05 | B25: A-01 | C25: 중앙구 | D25: 50000 | E25: 49100 | F25: =E25/D25 -> 0.982 | G25: =E25-E20 -> 1600 | H25: =G25/E20 -> 0.033684211 | I25: =SUMIF($B$5:B25,B25,$E$5:E25) -> 230100 | J25: 하절기 시작
A26: 2025-05 | B26: A-02 | C26: 동부구 | D26: 35000 | E26: 34500 | F26: =E26/D26 -> 0.98571429 | G26: =E26-E21 -> 900 | H26: =G26/E21 -> 0.026785714 | I26: =SUMIF($B$5:B26,B26,$E$5:E26) -> 164100
A27: 2025-05 | B27: A-03 | C27: 서부구 | D27: 31000 | E27: 30600 | F27: =E27/D27 -> 0.98709677 | G27: =E27-E22 -> 800 | H27: =G27/E22 -> 0.026845638 | I27: =SUMIF($B$5:B27,B27,$E$5:E27) -> 145300
A28: 2025-05 | B28: A-04 | C28: 남부구 | D28: 22000 | E28: 21800 | F28: =E28/D28 -> 0.99090909 | G28: =E28-E23 -> 1100 | H28: =G28/E23 -> 0.053140097 | I28: =SUMIF($B$5:B28,B28,$E$5:E28) -> 99800
A29: 2025-05 | B29: A-05 | C29: 북부구 | D29: 18000 | E29: 17900 | F29: =E29/D29 -> 0.99444444 | G29: =E29-E24 -> 1100 | H29: =G29/E24 -> 0.06547619 | I29: =SUMIF($B$5:B29,B29,$E$5:E29) -> 80600
A30: 2025-06 | B30: A-01 | C30: 중앙구 | D30: 52000 | E30: 51200 | F30: =E30/D30 -> 0.98461538 | G30: =E30-E25 -> 2100 | H30: =G30/E25 -> 0.042769857 | I30: =SUMIF($B$5:B30,B30,$E$5:E30) -> 281300
A31: 2025-06 | B31: A-02 | C31: 동부구 | D31: 36000 | E31: 35400 | F31: =E31/D31 -> 0.98333333 | G31: =E31-E26 -> 900 | H31: =G31/E26 -> 0.026086957 | I31: =SUMIF($B$5:B31,B31,$E$5:E31) -> 199500
A32: 2025-06 | B32: A-03 | C32: 서부구 | D32: 32000 | E32: 31500 | F32: =E32/D32 -> 0.984375 | G32: =E32-E27 -> 900 | H32: =G32/E27 -> 0.029411765 | I32: =SUMIF($B$5:B32,B32,$E$5:E32) -> 176800
A33: 2025-06 | B33: A-04 | C33: 남부구 | D33: 23000 | E33: 22600 | F33: =E33/D33 -> 0.9826087 | G33: =E33-E28 -> 800 | H33: =G33/E28 -> 0.036697248 | I33: =SUMIF($B$5:B33,B33,$E$5:E33) -> 122400
A34: 2025-06 | B34: A-05 | C34: 북부구 | D34: 19000 | E34: 18700 | F34: =E34/D34 -> 0.98421053 | G34: =E34-E29 -> 800 | H34: =G34/E29 -> 0.044692737 | I34: =SUMIF($B$5:B34,B34,$E$5:E34) -> 99300 | J34: 하절기 증가

Sheet ②수질검사
A1: 🔬 수질검사 결과 관리대장
A2: ○○시 상수도사업소 | 2025년 1월~6월
A4: 검사일 | B4: 검사지점 | C4: 잔류염소(mg/L) | D4: pH | E4: 탁도(NTU) | F4: 색도(도) | G4: 총대장균군 | H4: 일반세균(CFU/ml) | I4: 냄새 | J4: 맛 | K4: 판정 | L4: 비고
A5: 2025-01-08 | B5: 정수장 | C5: 0.52 | D5: 7.2 | E5: 0.12 | F5: 1 | G5: 불검출 | H5: 0 | I5: 이상없음 | J5: 이상없음 | K5: 적합
A6: 2025-01-08 | B6: 중앙구 배수지 | C6: 0.38 | D6: 7.1 | E6: 0.18 | F6: 1 | G6: 불검출 | H6: 0 | I6: 이상없음 | J6: 이상없음 | K6: 적합
A7: 2025-01-08 | B7: 동부구 말단 | C7: 0.21 | D7: 7.0 | E7: 0.25 | F7: 2 | G7: 불검출 | H7: 1 | I7: 이상없음 | J7: 이상없음 | K7: 적합
A8: 2025-02-12 | B8: 정수장 | C8: 0.55 | D8: 7.3 | E8: 0.10 | F8: 1 | G8: 불검출 | H8: 0 | I8: 이상없음 | J8: 이상없음 | K8: 적합
A9: 2025-02-12 | B9: 중앙구 배수지 | C9: 0.40 | D9: 7.2 | E9: 0.15 | F9: 1 | G9: 불검출 | H9: 0 | I9: 이상없음 | J9: 이상없음 | K9: 적합
A10: 2025-02-12 | B10: 서부구 말단 | C10: 0.19 | D10: 6.9 | E10: 0.31 | F10: 2 | G10: 불검출 | H10: 2 | I10: 이상없음 | J10: 이상없음 | K10: 적합 | L10: 말단 염소 낮음
A11: 2025-03-10 | B11: 정수장 | C11: 0.58 | D11: 7.4 | E11: 0.08 | F11: 1 | G11: 불검출 | H11: 0 | I11: 이상없음 | J11: 이상없음 | K11: 적합
A12: 2025-03-10 | B12: 중앙구 배수지 | C12: 0.42 | D12: 7.2 | E12: 0.14 | F12: 1 | G12: 불검출 | H12: 0 | I12: 이상없음 | J12: 이상없음 | K12: 적합
A13: 2025-03-10 | B13: 남부구 말단 | C13: 0.25 | D13: 7.1 | E13: 0.22 | F13: 1 | G13: 불검출 | H13: 0 | I13: 이상없음 | J13: 이상없음 | K13: 적합
A14: 2025-04-09 | B14: 정수장 | C14: 0.60 | D14: 7.5 | E14: 0.07 | F14: 1 | G14: 불검출 | H14: 0 | I14: 이상없음 | J14: 이상없음 | K14: 적합
A15: 2025-04-09 | B15: 중앙구 배수지 | C15: 0.45 | D15: 7.3 | E15: 0.12 | F15: 1 | G15: 불검출 | H15: 0 | I15: 이상없음 | J15: 이상없음 | K15: 적합
A16: 2025-04-09 | B16: 북부구 말단 | C16: 0.28 | D16: 7.1 | E16: 0.20 | F16: 1 | G16: 불검출 | H16: 0 | I16: 이상없음 | J16: 이상없음 | K16: 적합
A17: 2025-05-14 | B17: 정수장 | C17: 0.62 | D17: 7.5 | E17: 0.06 | F17: 1 | G17: 불검출 | H17: 0 | I17: 이상없음 | J17: 이상없음 | K17: 적합
A18: 2025-05-14 | B18: 동부구 배수지 | C18: 0.41 | D18: 7.2 | E18: 0.17 | F18: 2 | G18: 불검출 | H18: 1 | I18: 이상없음 | J18: 이상없음 | K18: 적합
A19: 2025-05-14 | B19: 서부구 말단 | C19: 0.22 | D19: 7.0 | E19: 0.28 | F19: 2 | G19: 불검출 | H19: 1 | I19: 이상없음 | J19: 이상없음 | K19: 적합
A20: 2025-06-11 | B20: 정수장 | C20: 0.65 | D20: 7.6 | E20: 0.05 | F20: 1 | G20: 불검출 | H20: 0 | I20: 이상없음 | J20: 이상없음 | K20: 적합 | L20: 하절기 관리강화
A21: 2025-06-11 | B21: 중앙구 배수지 | C21: 0.48 | D21: 7.3 | E21: 0.13 | F21: 1 | G21: 불검출 | H21: 0 | I21: 이상없음 | J21: 이상없음 | K21: 적합
A22: 2025-06-11 | B22: 남부구 말단 | C22: 0.30 | D22: 7.2 | E22: 0.21 | F22: 1 | G22: 불검출 | H22: 0 | I22: 이상없음 | J22: 이상없음 | K22: 적합

Sheet ③누수_유수율
A1: 📊 누수 및 유수율 관리대장
A2: ○○시 상수도사업소 | 2025년 1월~6월
A4: 연월 | B4: 총생산수량(㎥) | C4: 총급수수량(㎥) | D4: 누수량(㎥) | E4: 유수율(%) | F4: 무수율(%) | G4: 누수건수(건) | H4: 긴급복구(건) | I4: 복구완료율(%) | J4: 목표유수율(%) | K4: 달성여부 | L4: 비고
A5: 2025-01 | B5: 145000 | C5: 136000 | D5: 10000 | E5: =C5/B5 -> 0.93793103 | F5: =D5/B5 -> 0.068965517 | G5: 12 | H5: 11 | I5: =H5/G5 -> 0.91666667 | J5: 0.88 | K5: =IF(E5>=J5,"✅달성","❌미달") -> ✅달성 | L5: 동절기 누수 많음
A6: 2025-02 | B6: 142000 | C6: 134500 | D6: 7500 | E6: =C6/B6 -> 0.9471831 | F6: =D6/B6 -> 0.052816901 | G6: 9 | H6: 9 | I6: =H6/G6 -> 1 | J6: 0.88 | K6: =IF(E6>=J6,"✅달성","❌미달") -> ✅달성
A7: 2025-03 | B7: 149000 | C7: 140800 | D7: 2333 | E7: =C7/B7 -> 0.94496644 | F7: =D7/B7 -> 0.015657718 | G7: 11 | H7: 10 | I7: =H7/G7 -> 0.90909091 | J7: 0.88 | K7: =IF(E7>=J7,"✅달성","❌미달") -> ✅달성
A8: 2025-04 | B8: 154000 | C8: 146200 | D8: 4444 | E8: =C8/B8 -> 0.94935065 | F8: =D8/B8 -> 0.028857143 | G8: 8 | H8: 8 | I8: =H8/G8 -> 1 | J8: 0.9 | K8: =IF(E8>=J8,"✅달성","❌미달") -> ✅달성
A9: 2025-05 | B9: 160000 | C9: 152500 | D9: 7500 | E9: =C9/B9 -> 0.953125 | F9: =D9/B9 -> 0.046875 | G9: 8 | H9: 7 | I9: =H9/G9 -> 0.875 | J9: 0.9 | K9: =IF(E9>=J9,"✅달성","❌미달") -> ✅달성
A10: 2025-06 | B10: 165000 | C10: 567677 | D10: 7800 | E10: =C10/B10 -> 3.4404667 | F10: =D10/B10 -> 0.047272727 | G10: 7 | H10: 8 | I10: =H10/G10 -> 1.1428571 | J10: 0.9 | K10: =IF(E10>=J10,"✅달성","❌미달") -> ✅달성 | L10: 하절기 증가

Sheet ④요금수입
A1: 💰 요금수입 관리대장
A2: ○○시 상수도사업소 | 2025년 1월~6월
A4: 연월 | B4: 고지금액(원) | C4: 수납금액(원) | D4: 수납율(%) | E4: 체납금액(원) | F4: 체납건수(건) | G4: 전월체납이월(원) | H4: 당월체납합계(원) | I4: 징수율(%) | J4: 면제·감면(원) | K4: 비고
A5: 2025-01 | B5: 185200000 | C5: 181356000 | D5: =C5/B5 -> 0.97924406 | E5: 3844000 | F5: 42 | G5: 2100000 | H5: =E5+G5 -> 5944000 | I5: =C5/(B5+G5) -> 0.96826482 | J5: 320000 | K5: 동절기 고지
A6: 2025-02 | B6: 179800000 | C6: 176204000 | D6: =C6/B6 -> 0.98 | E6: 3596000 | F6: 38 | G6: 3844000 | H6: =E6+G6 -> 7440000 | I6: =C6/(B6+G6) -> 0.95948683 | J6: 280000
A7: 2025-03 | B7: 192500000 | C7: 188930000 | D7: =C7/B7 -> 0.98145455 | E7: 3570000 | F7: 35 | G7: 3596000 | H7: =E7+G7 -> 7166000 | I7: =C7/(B7+G7) -> 0.96345667 | J7: 350000
A8: 2025-04 | B8: 198700000 | C8: 195726000 | D8: =C8/B8 -> 0.98503271 | E8: 2974000 | F8: 30 | G8: 3570000 | H8: =E8+G8 -> 6544000 | I8: =C8/(B8+G8) -> 0.9676472 | J8: 410000
A9: 2025-05 | B9: 206300000 | C9: 203418000 | D9: =C9/B9 -> 0.98603005 | E9: 2882000 | F9: 28 | G9: 2974000 | H9: =E9+G9 -> 5856000 | I9: =C9/(B9+G9) -> 0.97201755 | J9: 380000
A10: 2025-06 | B10: 215800000 | C10: 212813000 | D10: =C10/B10 -> 0.98615848 | E10: 2987000 | F10: 31 | G10: 2882000 | H10: =E10+G10 -> 5869000 | I10: =C10/(B10+G10) -> 0.97316194 | J10: 450000 | K10: 하절기 고지

Sheet ⑤민원관리
A1: 📞 민원 처리 관리대장
A2: ○○시 상수도사업소 | 2025년 1월~6월
A4: 연월 | B4: 민원유형 | C4: 접수건수(건) | D4: 처리완료(건) | E4: 처리중(건) | F4: 평균처리일수 | G4: 기한초과(건) | H4: 만족도점수 | I4: 전월대비증감 | J4: 비고
A5: 2025-01 | B5: 수도누수신고 | C5: 18 | D5: 17 | E5: =C5-D5 -> 1 | F5: 1.8 | G5: 0 | H5: 4.2
A6: 2025-01 | B6: 요금이의신청 | C6: 5 | D6: 5 | E6: =C6-D6 -> 0 | F6: 3.2 | G6: 0 | H6: 3.8
A7: 2025-01 | B7: 수압불량 | C7: 8 | D7: 7 | E7: =C7-D7 -> 1 | F7: 2.1 | G7: 0 | H7: 4
A8: 2025-01 | B8: 단수불편 | C8: 3 | D8: 3 | E8: =C8-D8 -> 0 | F8: 0.5 | G8: 0 | H8: 3.5 | J8: 동결로 인한 단수
A9: 2025-02 | B9: 수도누수신고 | C9: 14 | D9: 14 | E9: =C9-D9 -> 0 | F9: 1.6 | G9: 0 | H9: 4.3
A10: 2025-02 | B10: 요금이의신청 | C10: 4 | D10: 4 | E10: =C10-D10 -> 0 | F10: 2.8 | G10: 0 | H10: 4.1
A11: 2025-02 | B11: 수압불량 | C11: 6 | D11: 5 | E11: =C11-D11 -> 1 | F11: 2.4 | G11: 0 | H11: 3.9
A12: 2025-02 | B12: 단수불편 | C12: 2 | D12: 2 | E12: =C12-D12 -> 0 | F12: 0.8 | G12: 0 | H12: 4
A13: 2025-03 | B13: 수도누수신고 | C13: 16 | D13: 15 | E13: =C13-D13 -> 1 | F13: 1.7 | G13: 0 | H13: 4.2
A14: 2025-03 | B14: 요금이의신청 | C14: 6 | D14: 6 | E14: =C14-D14 -> 0 | F14: 3 | G14: 0 | H14: 4
A15: 2025-03 | B15: 수압불량 | C15: 9 | D15: 8 | E15: =C15-D15 -> 1 | F15: 2.2 | G15: 1 | H15: 3.7 | J15: 처리지연 1건
A16: 2025-03 | B16: 기타불편 | C16: 4 | D16: 4 | E16: =C16-D16 -> 0 | F16: 1.5 | G16: 0 | H16: 4.1
A17: 2025-04 | B17: 수도누수신고 | C17: 12 | D17: 12 | E17: =C17-D17 -> 0 | F17: 1.5 | G17: 0 | H17: 4.5
A18: 2025-04 | B18: 요금이의신청 | C18: 3 | D18: 3 | E18: =C18-D18 -> 0 | F18: 2.5 | G18: 0 | H18: 4.3
A19: 2025-04 | B19: 수압불량 | C19: 5 | D19: 5 | E19: =C19-D19 -> 0 | F19: 1.9 | G19: 0 | H19: 4.2
A20: 2025-04 | B20: 기타불편 | C20: 3 | D20: 3 | E20: =C20-D20 -> 0 | F20: 1.2 | G20: 0 | H20: 4.4
A21: 2025-05 | B21: 수도누수신고 | C21: 15 | D21: 14 | E21: =C21-D21 -> 1 | F21: 1.6 | G21: 0 | H21: 4.3
A22: 2025-05 | B22: 요금이의신청 | C22: 4 | D22: 4 | E22: =C22-D22 -> 0 | F22: 2.7 | G22: 0 | H22: 4.1
A23: 2025-05 | B23: 수압불량 | C23: 7 | D23: 6 | E23: =C23-D23 -> 1 | F23: 2 | G23: 0 | H23: 4 | J23: 하절기 증가
A24: 2025-05 | B24: 단수불편 | C24: 2 | D24: 2 | E24: =C24-D24 -> 0 | F24: 0.7 | G24: 0 | H24: 4.2
A25: 2025-06 | B25: 수도누수신고 | C25: 20 | D25: 18 | E25: =C25-D25 -> 2 | F25: 1.9 | G25: 1 | H25: 4.1 | J25: 하절기 급증
A26: 2025-06 | B26: 요금이의신청 | C26: 5 | D26: 5 | E26: =C26-D26 -> 0 | F26: 3.1 | G26: 0 | H26: 4
A27: 2025-06 | B27: 수압불량 | C27: 10 | D27: 9 | E27: =C27-D27 -> 1 | F27: 2.3 | G27: 0 | H27: 3.9
A28: 2025-06 | B28: 단수불편 | C28: 4 | D28: 3 | E28: =C28-D28 -> 1 | F28: 1.2 | G28: 0 | H28: 3.6

Sheet ⑥시설물점검
A1: 🔧 시설물 점검 관리대장
A2: ○○시 상수도사업소 | 2025년 1월~6월
A4: 점검일 | B4: 시설유형 | C4: 시설명 | D4: 점검항목 | E4: 점검결과 | F4: 이상유무 | G4: 조치사항 | H4: 조치완료일 | I4: 담당자 | J4: 다음점검예정일 | K4: 비고
A5: 2025-01-06 | B5: 정수장 | C5: ○○정수장 | D5: 여과지 점검 | E5: 정상 | F5: 이상없음 | G5: 해당없음 | I5: 김상수 | J5: 2025-04-07
A6: 2025-01-06 | B6: 정수장 | C6: ○○정수장 | D6: 소독설비 점검 | E6: 정상 | F6: 이상없음 | G6: 해당없음 | I6: 김상수 | J6: 2025-02-03
A7: 2025-01-10 | B7: 펌프장 | C7: A구역 가압장 | D7: 펌프 성능시험 | E7: 경미한이상 | F7: 진동 발생 | G7: 베어링 교체 | H7: 2025-01-15 | I7: 이관리 | J7: 2025-04-10 | K7: 베어링 교체 완료
A8: 2025-01-15 | B8: 배수지 | C8: 중앙 배수지 | D8: 저수량 점검 | E8: 정상 | F8: 이상없음 | G8: 해당없음 | I8: 박시설 | J8: 2025-04-15
A9: 2025-02-03 | B9: 정수장 | C9: ○○정수장 | D9: 소독설비 점검 | E9: 정상 | F9: 이상없음 | G9: 해당없음 | I9: 김상수 | J9: 2025-03-03
A10: 2025-02-10 | B10: 배수관망 | C10: B구역 배수관 | D10: 관망 압력점검 | E10: 정상 | F10: 이상없음 | G10: 해당없음 | I10: 이관리 | J10: 2025-05-10
A11: 2025-03-03 | B11: 정수장 | C11: ○○정수장 | D11: 소독설비 점검 | E11: 정상 | F11: 이상없음 | G11: 해당없음 | I11: 김상수 | J11: 2025-04-03
A12: 2025-03-12 | B12: 배수지 | C12: 동부 배수지 | D12: 누수 여부 점검 | E12: 이상발견 | F12: 균열 발생 | G12: 균열 보수 | H12: 2025-03-20 | I12: 박시설 | J12: 2025-06-12 | K12: 균열 보수 완료
A13: 2025-04-03 | B13: 정수장 | C13: ○○정수장 | D13: 소독설비 점검 | E13: 정상 | F13: 이상없음 | G13: 해당없음 | I13: 김상수 | J13: 2025-05-05
A14: 2025-04-07 | B14: 정수장 | C14: ○○정수장 | D14: 여과지 점검 | E14: 정상 | F14: 이상없음 | G14: 해당없음 | I14: 김상수 | J14: 2025-07-07
A15: 2025-04-10 | B15: 펌프장 | C15: A구역 가압장 | D15: 펌프 성능시험 | E15: 정상 | F15: 이상없음 | G15: 해당없음 | I15: 이관리 | J15: 2025-07-10
A16: 2025-05-05 | B16: 정수장 | C16: ○○정수장 | D16: 소독설비 점검 | E16: 정상 | F16: 이상없음 | G16: 해당없음 | I16: 김상수 | J16: 2025-06-02
A17: 2025-05-15 | B17: 배수관망 | C17: C구역 배수관 | D17: 관망 압력점검 | E17: 경미한이상 | F17: 압력저하 | G17: 밸브 조정 | H17: 2025-05-16 | I17: 이관리 | J17: 2025-08-15
A18: 2025-06-02 | B18: 정수장 | C18: ○○정수장 | D18: 소독설비 점검 | E18: 정상 | F18: 이상없음 | G18: 해당없음 | I18: 김상수 | J18: 2025-07-07 | K18: 하절기 강화
A19: 2025-06-12 | B19: 배수지 | C19: 동부 배수지 | D19: 청소 및 점검 | E19: 정상 | F19: 이상없음 | G19: 해당없음 | I19: 박시설 | J19: 2025-09-12 | K19: 연 2회 청소

Sheet ⑦예산집행
A1: 📋 예산 집행 관리대장
A2: ○○시 상수도사업소 | 2025년 1월~6월
A4: 연월 | B4: 예산항목 | C4: 예산액(원) | D4: 집행액(원) | E4: 집행율(%) | F4: 잔액(원) | G4: 전월누계집행(원) | H4: 누계집행(원) | I4: 누계집행율(%) | J4: 비고
A5: 2025-01 | B5: 인건비 | C5: 25000000 | D5: 24850000 | E5: =D5/C5 -> 0.994 | F5: =C5-D5 -> 150000 | G5: 0 | H5: =G5+D5 -> 24850000 | I5: =H5/C5 -> 0.994
A6: 2025-01 | B6: 운영비 | C6: 8500000 | D6: 7920000 | E6: =D6/C6 -> 0.93176471 | F6: =C6-D6 -> 580000 | G6: 0 | H6: =G6+D6 -> 7920000 | I6: =H6/C6 -> 0.93176471
A7: 2025-01 | B7: 시설유지보수 | C7: 15000000 | D7: 9800000 | E7: =D7/C7 -> 0.65333333 | F7: =C7-D7 -> 5200000 | G7: 0 | H7: =G7+D7 -> 9800000 | I7: =H7/C7 -> 0.65333333 | J7: 베어링 교체
A8: 2025-01 | B8: 약품비 | C8: 6000000 | D8: 5850000 | E8: =D8/C8 -> 0.975 | F8: =C8-D8 -> 150000 | G8: 0 | H8: =G8+D8 -> 5850000 | I8: =H8/C8 -> 0.975 | J8: 염소 구매
A9: 2025-02 | B9: 인건비 | C9: 25000000 | D9: 24950000 | E9: =D9/C9 -> 0.998 | F9: =C9-D9 -> 50000 | G9: =H5 -> 24850000 | H9: =G9+D9 -> 49800000 | I9: =H9/C9 -> 1.992
A10: 2025-02 | B10: 운영비 | C10: 8500000 | D10: 8100000 | E10: =D10/C10 -> 0.95294118 | F10: =C10-D10 -> 400000 | G10: =H6 -> 7920000 | H10: =G10+D10 -> 16020000 | I10: =H10/C10 -> 1.8847059
A11: 2025-02 | B11: 시설유지보수 | C11: 15000000 | D11: 4200000 | E11: =D11/C11 -> 0.28 | F11: =C11-D11 -> 10800000 | G11: =H7 -> 9800000 | H11: =G11+D11 -> 14000000 | I11: =H11/C11 -> 0.93333333
A12: 2025-02 | B12: 약품비 | C12: 6000000 | D12: 5920000 | E12: =D12/C12 -> 0.98666667 | F12: =C12-D12 -> 80000 | G12: =H8 -> 5850000 | H12: =G12+D12 -> 11770000 | I12: =H12/C12 -> 1.9616667
A13: 2025-03 | B13: 인건비 | C13: 25000000 | D13: 24900000 | E13: =D13/C13 -> 0.996 | F13: =C13-D13 -> 100000 | G13: =H9 -> 49800000 | H13: =G13+D13 -> 74700000 | I13: =H13/C13 -> 2.988
A14: 2025-03 | B14: 운영비 | C14: 8500000 | D14: 8250000 | E14: =D14/C14 -> 0.97058824 | F14: =C14-D14 -> 250000 | G14: =H10 -> 16020000 | H14: =G14+D14 -> 24270000 | I14: =H14/C14 -> 2.8552941
A15: 2025-03 | B15: 시설유지보수 | C15: 15000000 | D15: 12500000 | E15: =D15/C15 -> 0.83333333 | F15: =C15-D15 -> 2500000 | G15: =H11 -> 14000000 | H15: =G15+D15 -> 26500000 | I15: =H15/C15 -> 1.7666667 | J15: 균열 보수
A16: 2025-03 | B16: 약품비 | C16: 6000000 | D16: 5780000 | E16: =D16/C16 -> 0.96333333 | F16: =C16-D16 -> 220000 | G16: =H12 -> 11770000 | H16: =G16+D16 -> 17550000 | I16: =H16/C16 -> 2.925
A17: 2025-04 | B17: 인건비 | C17: 25000000 | D17: 25000000 | E17: =D17/C17 -> 1 | F17: =C17-D17 -> 0 | G17: =H13 -> 74700000 | H17: =G17+D17 -> 99700000 | I17: =H17/C17 -> 3.988
A18: 2025-04 | B18: 운영비 | C18: 8500000 | D18: 8320000 | E18: =D18/C18 -> 0.97882353 | F18: =C18-D18 -> 180000 | G18: =H14 -> 24270000 | H18: =G18+D18 -> 32590000 | I18: =H18/C18 -> 3.8341176
A19: 2025-04 | B19: 시설유지보수 | C19: 15000000 | D19: 5600000 | E19: =D19/C19 -> 0.37333333 | F19: =C19-D19 -> 9400000 | G19: =H15 -> 26500000 | H19: =G19+D19 -> 32100000 | I19: =H19/C19 -> 2.14
A20: 2025-04 | B20: 약품비 | C20: 6000000 | D20: 5900000 | E20: =D20/C20 -> 0.98333333 | F20: =C20-D20 -> 100000 | G20: =H16 -> 17550000 | H20: =G20+D20 -> 23450000 | I20: =H20/C20 -> 3.9083333
A21: 2025-05 | B21: 인건비 | C21: 25000000 | D21: 24980000 | E21: =D21/C21 -> 0.9992 | F21: =C21-D21 -> 20000 | G21: =H17 -> 99700000 | H21: =G21+D21 -> 124680000 | I21: =H21/C21 -> 4.9872
A22: 2025-05 | B22: 운영비 | C22: 8500000 | D22: 8400000 | E22: =D22/C22 -> 0.98823529 | F22: =C22-D22 -> 100000 | G22: =H18 -> 32590000 | H22: =G22+D22 -> 40990000 | I22: =H22/C22 -> 4.8223529
A23: 2025-05 | B23: 시설유지보수 | C23: 15000000 | D23: 7800000 | E23: =D23/C23 -> 0.52 | F23: =C23-D23 -> 7200000 | G23: =H19 -> 32100000 | H23: =G23+D23 -> 39900000 | I23: =H23/C23 -> 2.66 | J23: 밸브 조정
A24: 2025-05 | B24: 약품비 | C24: 6000000 | D24: 6000000 | E24: =D24/C24 -> 1 | F24: =C24-D24 -> 0 | G24: =H20 -> 23450000 | H24: =G24+D24 -> 29450000 | I24: =H24/C24 -> 4.9083333 | J24: 하절기 증가
A25: 2025-06 | B25: 인건비 | C25: 25000000 | D25: 24970000 | E25: =D25/C25 -> 0.9988 | F25: =C25-D25 -> 30000 | G25: =H21 -> 124680000 | H25: =G25+D25 -> 149650000 | I25: =H25/C25 -> 5.986
A26: 2025-06 | B26: 운영비 | C26: 8500000 | D26: 8480000 | E26: =D26/C26 -> 0.99764706 | F26: =C26-D26 -> 20000 | G26: =H22 -> 40990000 | H26: =G26+D26 -> 49470000 | I26: =H26/C26 -> 5.82
A27: 2025-06 | B27: 시설유지보수 | C27: 15000000 | D27: 8200000 | E27: =D27/C27 -> 0.54666667 | F27: =C27-D27 -> 6800000 | G27: =H23 -> 39900000 | H27: =G27+D27 -> 48100000 | I27: =H27/C27 -> 3.2066667
A28: 2025-06 | B28: 약품비 | C28: 6000000 | D28: 6000000 | E28: =D28/C28 -> 1 | F28: =C28-D28 -> 0 | G28: =H24 -> 29450000 | H28: =G28+D28 -> 35450000 | I28: =H28/C28 -> 5.9083333
